Workbook

Sheet Sheet1
B1: Taxa_S | C1: Individuals | D1: Dominance_D | E1: Simpson_1-D | F1: Shannon_H | G1: Evenness_e^H/S | H1: Brillouin | I1: Menhinick | J1: Margalef | K1: Equitability_J | L1: Fisher_alpha | M1: Berger-Parker | N1: Chao-1
A2: S1S1P | B2: 13 | C2: 75 | D2: 0.4247 | E2: 0.5753 | F2: 1.484 | G2: 0.3392 | H2: 1.281 | I2: 1.501 | J2: 2.779 | K2: 0.5785 | L2: 4.54 | M2: 0.64 | N2: 16.33
A3: S1S1N | B3: 20 | C3: 59 | D3: 0.2611 | E3: 0.7389 | F3: 2.104 | G3: 0.4099 | H3: 1.743 | I3: 2.604 | J3: 4.66 | K3: 0.7023 | L3: 10.65 | M3: 0.4915 | N3: 39.5
A4: S1S2P | B4: 15 | C4: 89 | D4: 0.4806 | E4: 0.5194 | F4: 1.383 | G4: 0.2657 | H4: 1.193 | I4: 1.59 | J4: 3.119 | K4: 0.5106 | L4: 5.168 | M4: 0.6854 | N4: 24.33
A5: S1S2N | B5: 5 | C5: 22 | D5: 0.4628 | E5: 0.5372 | F5: 1.046 | G5: 0.5692 | H5: 0.8406 | I5: 1.066 | J5: 1.294 | K5: 0.6498 | L5: 2.019 | M5: 0.6364 | N5: 8
A6: S2S1P | B6: 13 | C6: 50 | D6: 0.256 | E6: 0.744 | F6: 1.807 | G6: 0.4686 | H6: 1.525 | I6: 1.838 | J6: 3.067 | K6: 0.7044 | L6: 5.705 | M6: 0.42 | N6: 27
A7: S2S1N | B7: 19 | C7: 65 | D7: 0.128 | E7: 0.872 | F7: 2.428 | G7: 0.5969 | H7: 2.083 | I7: 2.357 | J7: 4.312 | K7: 0.8248 | L7: 9.031 | M7: 0.2615 | N7: 34
A8: S2S2P | B8: 5 | C8: 7 | D8: 0.2245 | E8: 0.7755 | F8: 1.55 | G8: 0.9421 | H8: 1.02 | I8: 1.89 | J8: 2.056 | K8: 0.963 | L8: 7.824 | M8: 0.2857 | N8: 6
A9: S3S1P | B9: 9 | C9: 34 | D9: 0.2941 | E9: 0.7059 | F9: 1.638 | G9: 0.5719 | H9: 1.353 | I9: 1.543 | J9: 2.269 | K9: 0.7457 | L9: 3.996 | M9: 0.5 | N9: 12
A10: S3S1N | B10: 3 | C10: 3 | D10: 0.3333 | E10: 0.6667 | F10: 1.099 | G10: 1 | H10: 0.5973 | I10: 1.732 | J10: 1.82 | K10: 1 | L10: 0 | M10: 0.3333 | N10: 6
A11: S3S2P | B11: 4 | C11: 6 | D11: 0.3333 | E11: 0.6667 | F11: 1.242 | G11: 0.866 | H11: 0.7979 | I11: 1.633 | J11: 1.674 | K11: 0.8962 | L11: 5.245 | M11: 0.5 | N11: 7
A12: S3S2N | B12: 7 | C12: 29 | D12: 0.2866 | E12: 0.7134 | F12: 1.496 | G12: 0.6375 | H12: 1.241 | I12: 1.3 | J12: 1.782 | K12: 0.7686 | L12: 2.931 | M12: 0.4138 | N12: 8.5
A13: S4S1P | B13: 16 | C13: 996 | D13: 0.7626 | E13: 0.2374 | F13: 0.5839 | G13: 0.1121 | H13: 0.5615 | I13: 0.507 | J13: 2.173 | K13: 0.2106 | L13: 2.707 | M13: 0.8695 | N13: 17.67
A14: S4S1N | B14: 12 | C14: 384 | D14: 0.6643 | E14: 0.3357 | F14: 0.7479 | G14: 0.1761 | H14: 0.7083 | I14: 0.6124 | J14: 1.849 | K14: 0.301 | L14: 2.352 | M14: 0.8047 | N14: 33
A15: S4S2P | B15: 4 | C15: 12 | D15: 0.3472 | E15: 0.6528 | F15: 1.199 | G15: 0.8291 | H15: 0.9103 | I15: 1.155 | J15: 1.207 | K15: 0.8648 | L15: 2.101 | M15: 0.5 | N15: 4
A16: S4S2N | B16: 2 | C16: 2 | D16: 0.5 | E16: 0.5 | F16: 0.6931 | G16: 1 | H16: 0.3466 | I16: 1.414 | J16: 1.443 | K16: 1 | L16: 0 | M16: 0.5 | N16: 3
A17: S5S1P | B17: 12 | C17: 29 | D17: 0.1391 | E17: 0.8609 | F17: 2.22 | G17: 0.7673 | H17: 1.777 | I17: 2.228 | J17: 3.267 | K17: 0.8934 | L17: 7.669 | M17: 0.2759 | N17: 14
A18: S5S1N | B18: 17 | C18: 309 | D18: 0.6705 | E18: 0.3295 | F18: 0.8931 | G18: 0.1437 | H18: 0.823 | I18: 0.9671 | J18: 2.791 | K18: 0.3152 | L18: 3.87 | M18: 0.8155 | N18: 26.33
A19: S5S2P | B19: 4 | C19: 21 | D19: 0.6054 | E19: 0.3946 | F19: 0.7751 | G19: 0.5427 | H19: 0.6151 | I19: 0.8729 | J19: 0.9854 | K19: 0.5591 | L19: 1.465 | M19: 0.7619 | N19: 5
A20: S6S1P | B20: 11 | C20: 70 | D20: 0.2433 | E20: 0.7567 | F20: 1.686 | G20: 0.4907 | H20: 1.498 | I20: 1.315 | J20: 2.354 | K20: 0.7031 | L20: 3.666 | M20: 0.3286 | N20: 18.5
A21: S6S1N | B21: 5 | C21: 10 | D21: 0.4 | E21: 0.6 | F21: 1.228 | G21: 0.6826 | H21: 0.8525 | I21: 1.581 | J21: 1.737 | K21: 0.7627 | L21: 3.98 | M21: 0.6 | N21: 11
A22: S6S2P | B22: 5 | C22: 89 | D22: 0.5377 | E22: 0.4623 | F22: 0.8296 | G22: 0.4585 | H22: 0.7632 | I22: 0.53 | J22: 0.8911 | K22: 0.5155 | L22: 1.145 | M22: 0.6854 | N22: 5
A23: S6S2N | B23: 1 | C23: 5 | D23: 1 | E23: 0 | F23: 0 | G23: 1 | H23: 0 | I23: 0.4472 | J23: 0 | L23: 0.3759 | M23: 1 | N23: 1
A24: S7S1P | B24: 11 | C24: 198 | D24: 0.4552 | E24: 0.5448 | F24: 1.238 | G24: 0.3134 | H24: 1.159 | I24: 0.7817 | J24: 1.891 | K24: 0.5162 | L24: 2.511 | M24: 0.6515 | N24: 12
A25: S7S1N | B25: 14 | C25: 200 | D25: 0.6005 | E25: 0.3995 | F25: 1.046 | G25: 0.2033 | H25: 0.955 | I25: 0.9899 | J25: 2.454 | K25: 0.3963 | L25: 3.429 | M25: 0.77 | N25: 17.33
A26: S7S2P | B26: 5 | C26: 87 | D26: 0.5659 | E26: 0.4341 | F26: 0.8955 | G26: 0.4897 | H26: 0.8179 | I26: 0.5361 | J26: 0.8957 | K26: 0.5564 | L26: 1.153 | M26: 0.7356 | N26: 5
A27: S8S1P | B27: 18 | C27: 254 | D27: 0.4301 | E27: 0.5699 | F27: 1.432 | G27: 0.2325 | H27: 1.334 | I27: 1.129 | J27: 3.07 | K27: 0.4953 | L27: 4.426 | M27: 0.6378 | N27: 19.43
A28: S8S1N | B28: 17 | C28: 926 | D28: 0.7788 | E28: 0.2212 | F28: 0.5556 | G28: 0.1025 | H28: 0.5308 | I28: 0.5587 | J28: 2.342 | K28: 0.1961 | L28: 2.956 | M28: 0.879 | N28: 20.75
A29: S8S2P | B29: 9 | C29: 60 | D29: 0.2572 | E29: 0.7428 | F29: 1.622 | G29: 0.5627 | H29: 1.439 | I29: 1.162 | J29: 1.954 | K29: 0.7383 | L29: 2.936 | M29: 0.4167 | N29: 12
A30: S8S2N | B30: 9 | C30: 77 | D30: 0.5426 | E30: 0.4574 | F30: 1.093 | G30: 0.3316 | H30: 0.9567 | I30: 1.026 | J30: 1.842 | K30: 0.4976 | L30: 2.643 | M30: 0.7273 | N30: 10
A31: S9S1P | B31: 20 | C31: 120 | D31: 0.1538 | E31: 0.8463 | F31: 2.261 | G31: 0.4795 | H31: 2.04 | I31: 1.826 | J31: 3.969 | K31: 0.7547 | L31: 6.853 | M31: 0.2333 | N31: 21.88
A32: S9S1N | B32: 18 | C32: 122 | D32: 0.2068 | E32: 0.7932 | F32: 2.081 | G32: 0.4451 | H32: 1.881 | I32: 1.63 | J32: 3.539 | K32: 0.72 | L32: 5.829 | M32: 0.377 | N32: 20
A33: S9S2P | B33: 13 | C33: 48 | D33: 0.2778 | E33: 0.7222 | F33: 1.856 | G33: 0.4922 | H33: 1.553 | I33: 1.876 | J33: 3.1 | K33: 0.7236 | L33: 5.861 | M33: 0.5 | N33: 18
A34: S9S2N | B34: 5 | C34: 32 | D34: 0.418 | E34: 0.582 | F34: 1.119 | G34: 0.6121 | H34: 0.9536 | I34: 0.8839 | J34: 1.154 | K34: 0.695 | L34: 1.662 | M34: 0.5938 | N34: 6
A35: S10S1P | B35: 23 | C35: 90 | D35: 0.1299 | E35: 0.8701 | F35: 2.519 | G35: 0.5397 | H35: 2.202 | I35: 2.424 | J35: 4.889 | K35: 0.8033 | L35: 9.982 | M35: 0.2444 | N35: 28.14
A36: S10S1N | B36: 17 | C36: 153 | D36: 0.2581 | E36: 0.7419 | F36: 1.807 | G36: 0.3584 | H36: 1.661 | I36: 1.374 | J36: 3.181 | K36: 0.6378 | L36: 4.893 | M36: 0.4444 | N36: 21.2
A37: S10S2P | B37: 3 | C37: 4 | D37: 0.375 | E37: 0.625 | F37: 1.04 | G37: 0.9428 | H37: 0.6212 | I37: 1.5 | J37: 1.443 | K37: 0.9464 | L37: 5.453 | M37: 0.5 | N37: 3.5
A38: S10S2N | B38: 3 | C38: 14 | D38: 0.5 | E38: 0.5 | F38: 0.8305 | G38: 0.7648 | H38: 0.658 | I38: 0.8018 | J38: 0.7578 | K38: 0.7559 | L38: 1.171 | M38: 0.6429 | N38: 3

Sheet Div.seasons (All sites)
A1: Season | B1: Substrate | C1: Taxa_S | D1: Individuals | E1: Dominance_D | F1: Simpson_1-D | G1: Shannon_H | H1: Evenness_e^H/S | I1: Brillouin | J1: Menhinick | K1: Margalef | L1: Equitability_J | M1: Fisher_alpha | N1: Berger-Parker | O1: Chao-1
A2: 1 | B2: P | C2: 13 | D2: 75 | E2: 0.4247 | F2: 0.5753 | G2: 1.484 | H2: 0.3392 | I2: 1.281 | J2: 1.501 | K2: 2.779 | L2: 0.5785 | M2: 4.54 | N2: 0.64 | O2: 16.33
A3: 1 | B3: N | C3: 20 | D3: 59 | E3: 0.2611 | F3: 0.7389 | G3: 2.104 | H3: 0.4099 | I3: 1.743 | J3: 2.604 | K3: 4.66 | L3: 0.7023 | M3: 10.65 | N3: 0.4915 | O3: 39.5
A4: 1 | B4: P | C4: 13 | D4: 50 | E4: 0.256 | F4: 0.744 | G4: 1.807 | H4: 0.4686 | I4: 1.525 | J4: 1.838 | K4: 3.067 | L4: 0.7044 | M4: 5.705 | N4: 0.42 | O4: 27
A5: 1 | B5: N | C5: 19 | D5: 65 | E5: 0.128 | F5: 0.872 | G5: 2.428 | H5: 0.5969 | I5: 2.083 | J5: 2.357 | K5: 4.312 | L5: 0.8248 | M5: 9.031 | N5: 0.2615 | O5: 34
A6: 1 | B6: P | C6: 9 | D6: 34 | E6: 0.2941 | F6: 0.7059 | G6: 1.638 | H6: 0.5719 | I6: 1.353 | J6: 1.543 | K6: 2.269 | L6: 0.7457 | M6: 3.996 | N6: 0.5 | O6: 12
A7: 1 | B7: N | C7: 3 | D7: 3 | E7: 0.3333 | F7: 0.6667 | G7: 1.099 | H7: 1 | I7: 0.5973 | J7: 1.732 | K7: 1.82 | L7: 1 | M7: 0 | N7: 0.3333 | O7: 6
A8: 1 | B8: P | C8: 16 | D8: 996 | E8: 0.7626 | F8: 0.2374 | G8: 0.5839 | H8: 0.1121 | I8: 0.5615 | J8: 0.507 | K8: 2.173 | L8: 0.2106 | M8: 2.707 | N8: 0.8695 | O8: 17.67
A9: 1 | B9: N | C9: 12 | D9: 384 | E9: 0.6643 | F9: 0.3357 | G9: 0.7479 | H9: 0.1761 | I9: 0.7083 | J9: 0.6124 | K9: 1.849 | L9: 0.301 | M9: 2.352 | N9: 0.8047 | O9: 33
A10: 1 | B10: P | C10: 12 | D10: 29 | E10: 0.1391 | F10: 0.8609 | G10: 2.22 | H10: 0.7673 | I10: 1.777 | J10: 2.228 | K10: 3.267 | L10: 0.8934 | M10: 7.669 | N10: 0.2759 | O10: 14
A11: 1 | B11: N | C11: 17 | D11: 309 | E11: 0.6705 | F11: 0.3295 | G11: 0.8931 | H11: 0.1437 | I11: 0.823 | J11: 0.9671 | K11: 2.791 | L11: 0.3152 | M11: 3.87 | N11: 0.8155 | O11: 26.33
A12: 1 | B12: P | C12: 11 | D12: 70 | E12: 0.2433 | F12: 0.7567 | G12: 1.686 | H12: 0.4907 | I12: 1.498 | J12: 1.315 | K12: 2.354 | L12: 0.7031 | M12: 3.666 | N12: 0.3286 | O12: 18.5
A13: 1 | B13: N | C13: 5 | D13: 10 | E13: 0.4 | F13: 0.6 | G13: 1.228 | H13: 0.6826 | I13: 0.8525 | J13: 1.581 | K13: 1.737 | L13: 0.7627 | M13: 3.98 | N13: 0.6 | O13: 11
A14: 1 | B14: P | C14: 11 | D14: 198 | E14: 0.4552 | F14: 0.5448 | G14: 1.238 | H14: 0.3134 | I14: 1.159 | J14: 0.7817 | K14: 1.891 | L14: 0.5162 | M14: 2.511 | N14: 0.6515 | O14: 12
A15: 1 | B15: N | C15: 14 | D15: 200 | E15: 0.6005 | F15: 0.3995 | G15: 1.046 | H15: 0.2033 | I15: 0.955 | J15: 0.9899 | K15: 2.454 | L15: 0.3963 | M15: 3.429 | N15: 0.77 | O15: 17.33
A16: 1 | B16: P | C16: 18 | D16: 254 | E16: 0.4301 | F16: 0.5699 | G16: 1.432 | H16: 0.2325 | I16: 1.334 | J16: 1.129 | K16: 3.07 | L16: 0.4953 | M16: 4.426 | N16: 0.6378 | O16: 19.43
A17: 1 | B17: N | C17: 17 | D17: 926 | E17: 0.7788 | F17: 0.2212 | G17: 0.5556 | H17: 0.1025 | I17: 0.5308 | J17: 0.5587 | K17: 2.342 | L17: 0.1961 | M17: 2.956 | N17: 0.879 | O17: 20.75
A18: 1 | B18: P | C18: 20 | D18: 120 | E18: 0.1538 | F18: 0.8463 | G18: 2.261 | H18: 0.4795 | I18: 2.04 | J18: 1.826 | K18: 3.969 | L18: 0.7547 | M18: 6.853 | N18: 0.2333 | O18: 21.88
A19: 1 | B19: N | C19: 18 | D19: 122 | E19: 0.2068 | F19: 0.7932 | G19: 2.081 | H19: 0.4451 | I19: 1.881 | J19: 1.63 | K19: 3.539 | L19: 0.72 | M19: 5.829 | N19: 0.377 | O19: 20
A20: 1 | B20: P | C20: 23 | D20: 90 | E20: 0.1299 | F20: 0.8701 | G20: 2.519 | H20: 0.5397 | I20: 2.202 | J20: 2.424 | K20: 4.889 | L20: 0.8033 | M20: 9.982 | N20: 0.2444 | O20: 28.14
A21: 1 | B21: N | C21: 17 | D21: 153 | E21: 0.2581 | F21: 0.7419 | G21: 1.807 | H21: 0.3584 | I21: 1.661 | J21: 1.374 | K21: 3.181 | L21: 0.6378 | M21: 4.893 | N21: 0.4444 | O21: 21.2
A22: 2 | B22: P | C22: 15 | D22: 89 | E22: 0.4806 | F22: 0.5194 | G22: 1.383 | H22: 0.2657 | I22: 1.193 | J22: 1.59 | K22: 3.119 | L22: 0.5106 | M22: 5.168 | N22: 0.6854 | O22: 24.33
A23: 2 | B23: N | C23: 5 | D23: 22 | E23: 0.4628 | F23: 0.5372 | G23: 1.046 | H23: 0.5692 | I23: 0.8406 | J23: 1.066 | K23: 1.294 | L23: 0.6498 | M23: 2.019 | N23: 0.6364 | O23: 8
A24: 2 | B24: P | C24: 5 | D24: 7 | E24: 0.2245 | F24: 0.7755 | G24: 1.55 | H24: 0.9421 | I24: 1.02 | J24: 1.89 | K24: 2.056 | L24: 0.963 | M24: 7.824 | N24: 0.2857 | O24: 6
A25: 2 | B25: P | C25: 4 | D25: 6 | E25: 0.3333 | F25: 0.6667 | G25: 1.242 | H25: 0.866 | I25: 0.7979 | J25: 1.633 | K25: 1.674 | L25: 0.8962 | M25: 5.245 | N25: 0.5 | O25: 7
A26: 2 | B26: N | C26: 7 | D26: 29 | E26: 0.2866 | F26: 0.7134 | G26: 1.496 | H26: 0.6375 | I26: 1.241 | J26: 1.3 | K26: 1.782 | L26: 0.7686 | M26: 2.931 | N26: 0.4138 | O26: 8.5
A27: 2 | B27: P | C27: 4 | D27: 12 | E27: 0.3472 | F27: 0.6528 | G27: 1.199 | H27: 0.8291 | I27: 0.9103 | J27: 1.155 | K27: 1.207 | L27: 0.8648 | M27: 2.101 | N27: 0.5 | O27: 4
A28: 2 | B28: N | C28: 2 | D28: 2 | E28: 0.5 | F28: 0.5 | G28: 0.6931 | H28: 1 | I28: 0.3466 | J28: 1.414 | K28: 1.443 | L28: 1 | M28: 0 | N28: 0.5 | O28: 3
A29: 2 | B29: P | C29: 4 | D29: 21 | E29: 0.6054 | F29: 0.3946 | G29: 0.7751 | H29: 0.5427 | I29: 0.6151 | J29: 0.8729 | K29: 0.9854 | L29: 0.5591 | M29: 1.465 | N29: 0.7619 | O29: 5
A30: 2 | B30: P | C30: 5 | D30: 89 | E30: 0.5377 | F30: 0.4623 | G30: 0.8296 | H30: 0.4585 | I30: 0.7632 | J30: 0.53 | K30: 0.8911 | L30: 0.5155 | M30: 1.145 | N30: 0.6854 | O30: 5
A31: 2 | B31: N | C31: 1 | D31: 5 | E31: 1 | F31: 0 | G31: 0 | H31: 1 | I31: 0 | J31: 0.4472 | K31: 0 | M31: 0.3759 | N31: 1 | O31: 1
A32: 2 | B32: P | C32: 5 | D32: 87 | E32: 0.5659 | F32: 0.4341 | G32: 0.8955 | H32: 0.4897 | I32: 0.8179 | J32: 0.5361 | K32: 0.8957 | L32: 0.5564 | M32: 1.153 | N32: 0.7356 | O32: 5
A33: 2 | B33: P | C33: 9 | D33: 60 | E33: 0.2572 | F33: 0.7428 | G33: 1.622 | H33: 0.5627 | I33: 1.439 | J33: 1.162 | K33: 1.954 | L33: 0.7383 | M33: 2.936 | N33: 0.4167 | O33: 12
A34: 2 | B34: N | C34: 9 | D34: 77 | E34: 0.5426 | F34: 0.4574 | G34: 1.093 | H34: 0.3316 | I34: 0.9567 | J34: 1.026 | K34: 1.842 | L34: 0.4976 | M34: 2.643 | N34: 0.7273 | O34: 10
A35: 2 | B35: P | C35: 13 | D35: 48 | E35: 0.2778 | F35: 0.7222 | G35: 1.856 | H35: 0.4922 | I35: 1.553 | J35: 1.876 | K35: 3.1 | L35: 0.7236 | M35: 5.861 | N35: 0.5 | O35: 18
A36: 2 | B36: N | C36: 5 | D36: 32 | E36: 0.418 | F36: 0.582 | G36: 1.119 | H36: 0.6121 | I36: 0.9536 | J36: 0.8839 | K36: 1.154 | L36: 0.695 | M36: 1.662 | N36: 0.5938 | O36: 6
A37: 2 | B37: P | C37: 3 | D37: 4 | E37: 0.375 | F37: 0.625 | G37: 1.04 | H37: 0.9428 | I37: 0.6212 | J37: 1.5 | K37: 1.443 | L37: 0.9464 | M37: 5.453 | N37: 0.5 | O37: 3.5
A38: 2 | B38: N | C38: 3 | D38: 14 | E38: 0.5 | F38: 0.5 | G38: 0.8305 | H38: 0.7648 | I38: 0.658 | J38: 0.8018 | K38: 0.7578 | L38: 0.7559 | M38: 1.171 | N38: 0.6429 | O38: 3

Sheet Div.substrates (All sites)
A1: Season | B1: Substrate | C1: Taxa_S | D1: Individuals | E1: Dominance_D | F1: Simpson_1-D | G1: Shannon_H | H1: Evenness_e^H/S | I1: Brillouin | J1: Menhinick | K1: Margalef | L1: Equitability_J | M1: Fisher_alpha | N1: Berger-Parker | O1: Chao-1
A2: 1 | B2: N | C2: 20 | D2: 59 | E2: 0.2611 | F2: 0.7389 | G2: 2.104 | H2: 0.4099 | I2: 1.743 | J2: 2.604 | K2: 4.66 | L2: 0.7023 | M2: 10.65 | N2: 0.4915 | O2: 39.5
A3: 1 | B3: N | C3: 19 | D3: 65 | E3: 0.128 | F3: 0.872 | G3: 2.428 | H3: 0.5969 | I3: 2.083 | J3: 2.357 | K3: 4.312 | L3: 0.8248 | M3: 9.031 | N3: 0.2615 | O3: 34
A4: 1 | B4: N | C4: 3 | D4: 3 | E4: 0.3333 | F4: 0.6667 | G4: 1.099 | H4: 1 | I4: 0.5973 | J4: 1.732 | K4: 1.82 | L4: 1 | M4: 0 | N4: 0.3333 | O4: 6
A5: 1 | B5: N | C5: 12 | D5: 384 | E5: 0.6643 | F5: 0.3357 | G5: 0.7479 | H5: 0.1761 | I5: 0.7083 | J5: 0.6124 | K5: 1.849 | L5: 0.301 | M5: 2.352 | N5: 0.8047 | O5: 33
A6: 1 | B6: N | C6: 17 | D6: 309 | E6: 0.6705 | F6: 0.3295 | G6: 0.8931 | H6: 0.1437 | I6: 0.823 | J6: 0.9671 | K6: 2.791 | L6: 0.3152 | M6: 3.87 | N6: 0.8155 | O6: 26.33
A7: 1 | B7: N | C7: 5 | D7: 10 | E7: 0.4 | F7: 0.6 | G7: 1.228 | H7: 0.6826 | I7: 0.8525 | J7: 1.581 | K7: 1.737 | L7: 0.7627 | M7: 3.98 | N7: 0.6 | O7: 11
A8: 1 | B8: N | C8: 14 | D8: 200 | E8: 0.6005 | F8: 0.3995 | G8: 1.046 | H8: 0.2033 | I8: 0.955 | J8: 0.9899 | K8: 2.454 | L8: 0.3963 | M8: 3.429 | N8: 0.77 | O8: 17.33
A9: 1 | B9: N | C9: 17 | D9: 926 | E9: 0.7788 | F9: 0.2212 | G9: 0.5556 | H9: 0.1025 | I9: 0.5308 | J9: 0.5587 | K9: 2.342 | L9: 0.1961 | M9: 2.956 | N9: 0.879 | O9: 20.75
A10: 1 | B10: N | C10: 18 | D10: 122 | E10: 0.2068 | F10: 0.7932 | G10: 2.081 | H10: 0.4451 | I10: 1.881 | J10: 1.63 | K10: 3.539 | L10: 0.72 | M10: 5.829 | N10: 0.377 | O10: 20
A11: 1 | B11: N | C11: 17 | D11: 153 | E11: 0.2581 | F11: 0.7419 | G11: 1.807 | H11: 0.3584 | I11: 1.661 | J11: 1.374 | K11: 3.181 | L11: 0.6378 | M11: 4.893 | N11: 0.4444 | O11: 21.2
A12: 2 | B12: N | C12: 5 | D12: 22 | E12: 0.4628 | F12: 0.5372 | G12: 1.046 | H12: 0.5692 | I12: 0.8406 | J12: 1.066 | K12: 1.294 | L12: 0.6498 | M12: 2.019 | N12: 0.6364 | O12: 8
A13: 2 | B13: N | C13: 7 | D13: 29 | E13: 0.2866 | F13: 0.7134 | G13: 1.496 | H13: 0.6375 | I13: 1.241 | J13: 1.3 | K13: 1.782 | L13: 0.7686 | M13: 2.931 | N13: 0.4138 | O13: 8.5
A14: 2 | B14: N | C14: 2 | D14: 2 | E14: 0.5 | F14: 0.5 | G14: 0.6931 | H14: 1 | I14: 0.3466 | J14: 1.414 | K14: 1.443 | L14: 1 | M14: 0 | N14: 0.5 | O14: 3
A15: 2 | B15: N | C15: 1 | D15: 5 | E15: 1 | F15: 0 | G15: 0 | H15: 1 | I15: 0 | J15: 0.4472 | K15: 0 | M15: 0.3759 | N15: 1 | O15: 1
A16: 2 | B16: N | C16: 9 | D16: 77 | E16: 0.5426 | F16: 0.4574 | G16: 1.093 | H16: 0.3316 | I16: 0.9567 | J16: 1.026 | K16: 1.842 | L16: 0.4976 | M16: 2.643 | N16: 0.7273 | O16: 10
A17: 2 | B17: N | C17: 5 | D17: 32 | E17: 0.418 | F17: 0.582 | G17: 1.119 | H17: 0.6121 | I17: 0.9536 | J17: 0.8839 | K17: 1.154 | L17: 0.695 | M17: 1.662 | N17: 0.5938 | O17: 6
A18: 2 | B18: N | C18: 3 | D18: 14 | E18: 0.5 | F18: 0.5 | G18: 0.8305 | H18: 0.7648 | I18: 0.658 | J18: 0.8018 | K18: 0.7578 | L18: 0.7559 | M18: 1.171 | N18: 0.6429 | O18: 3
A19: 1 | B19: P | C19: 13 | D19: 75 | E19: 0.4247 | F19: 0.5753 | G19: 1.484 | H19: 0.3392 | I19: 1.281 | J19: 1.501 | K19: 2.779 | L19: 0.5785 | M19: 4.54 | N19: 0.64 | O19: 16.33
A20: 1 | B20: P | C20: 13 | D20: 50 | E20: 0.256 | F20: 0.744 | G20: 1.807 | H20: 0.4686 | I20: 1.525 | J20: 1.838 | K20: 3.067 | L20: 0.7044 | M20: 5.705 | N20: 0.42 | O20: 27
A21: 1 | B21: P | C21: 9 | D21: 34 | E21: 0.2941 | F21: 0.7059 | G21: 1.638 | H21: 0.5719 | I21: 1.353 | J21: 1.543 | K21: 2.269 | L21: 0.7457 | M21: 3.996 | N21: 0.5 | O21: 12
A22: 1 | B22: P | C22: 16 | D22: 996 | E22: 0.7626 | F22: 0.2374 | G22: 0.5839 | H22: 0.1121 | I22: 0.5615 | J22: 0.507 | K22: 2.173 | L22: 0.2106 | M22: 2.707 | N22: 0.8695 | O22: 17.67
A23: 1 | B23: P | C23: 12 | D23: 29 | E23: 0.1391 | F23: 0.8609 | G23: 2.22 | H23: 0.7673 | I23: 1.777 | J23: 2.228 | K23: 3.267 | L23: 0.8934 | M23: 7.669 | N23: 0.2759 | O23: 14
A24: 1 | B24: P | C24: 11 | D24: 70 | E24: 0.2433 | F24: 0.7567 | G24: 1.686 | H24: 0.4907 | I24: 1.498 | J24: 1.315 | K24: 2.354 | L24: 0.7031 | M24: 3.666 | N24: 0.3286 | O24: 18.5
A25: 1 | B25: P | C25: 11 | D25: 198 | E25: 0.4552 | F25: 0.5448 | G25: 1.238 | H25: 0.3134 | I25: 1.159 | J25: 0.7817 | K25: 1.891 | L25: 0.5162 | M25: 2.511 | N25: 0.6515 | O25: 12
A26: 1 | B26: P | C26: 18 | D26: 254 | E26: 0.4301 | F26: 0.5699 | G26: 1.432 | H26: 0.2325 | I26: 1.334 | J26: 1.129 | K26: 3.07 | L26: 0.4953 | M26: 4.426 | N26: 0.6378 | O26: 19.43
A27: 1 | B27: P | C27: 20 | D27: 120 | E27: 0.1538 | F27: 0.8463 | G27: 2.261 | H27: 0.4795 | I27: 2.04 | J27: 1.826 | K27: 3.969 | L27: 0.7547 | M27: 6.853 | N27: 0.2333 | O27: 21.88
A28: 1 | B28: P | C28: 23 | D28: 90 | E28: 0.1299 | F28: 0.8701 | G28: 2.519 | H28: 0.5397 | I28: 2.202 | J28: 2.424 | K28: 4.889 | L28: 0.8033 | M28: 9.982 | N28: 0.2444 | O28: 28.14
A29: 2 | B29: P | C29: 15 | D29: 89 | E29: 0.4806 | F29: 0.5194 | G29: 1.383 | H29: 0.2657 | I29: 1.193 | J29: 1.59 | K29: 3.119 | L29: 0.5106 | M29: 5.168 | N29: 0.6854 | O29: 24.33
A30: 2 | B30: P | C30: 5 | D30: 7 | E30: 0.2245 | F30: 0.7755 | G30: 1.55 | H30: 0.9421 | I30: 1.02 | J30: 1.89 | K30: 2.056 | L30: 0.963 | M30: 7.824 | N30: 0.2857 | O30: 6
A31: 2 | B31: P | C31: 4 | D31: 6 | E31: 0.3333 | F31: 0.6667 | G31: 1.242 | H31: 0.866 | I31: 0.7979 | J31: 1.633 | K31: 1.674 | L31: 0.8962 | M31: 5.245 | N31: 0.5 | O31: 7
A32: 2 | B32: P | C32: 4 | D32: 12 | E32: 0.3472 | F32: 0.6528 | G32: 1.199 | H32: 0.8291 | I32: 0.9103 | J32: 1.155 | K32: 1.207 | L32: 0.8648 | M32: 2.101 | N32: 0.5 | O32: 4
A33: 2 | B33: P | C33: 4 | D33: 21 | E33: 0.6054 | F33: 0.3946 | G33: 0.7751 | H33: 0.5427 | I33: 0.6151 | J33: 0.8729 | K33: 0.9854 | L33: 0.5591 | M33: 1.465 | N33: 0.7619 | O33: 5
A34: 2 | B34: P | C34: 5 | D34: 89 | E34: 0.5377 | F34: 0.4623 | G34: 0.8296 | H34: 0.4585 | I34: 0.7632 | J34: 0.53 | K34: 0.8911 | L34: 0.5155 | M34: 1.145 | N34: 0.6854 | O34: 5
A35: 2 | B35: P | C35: 5 | D35: 87 | E35: 0.5659 | F35: 0.4341 | G35: 0.8955 | H35: 0.4897 | I35: 0.8179 | J35: 0.5361 | K35: 0.8957 | L35: 0.5564 | M35: 1.153 | N35: 0.7356 | O35: 5
A36: 2 | B36: P | C36: 9 | D36: 60 | E36: 0.2572 | F36: 0.7428 | G36: 1.622 | H36: 0.5627 | I36: 1.439 | J36: 1.162 | K36: 1.954 | L36: 0.7383 | M36: 2.936 | N36: 0.4167 | O36: 12
A37: 2 | B37: P | C37: 13 | D37: 48 | E37: 0.2778 | F37: 0.7222 | G37: 1.856 | H37: 0.4922 | I37: 1.553 | J37: 1.876 | K37: 3.1 | L37: 0.7236 | M37: 5.861 | N37: 0.5 | O37: 18
A38: 2 | B38: P | C38: 3 | D38: 4 | E38: 0.375 | F38: 0.625 | G38: 1.04 | H38: 0.9428 | I38: 0.6212 | J38: 1.5 | K38: 1.443 | L38: 0.9464 | M38: 5.453 | N38: 0.5 | O38: 3.5

Sheet Plastic vs natural
A1: Season | B1: Taxa_S_Natural | C1: Taxa_S_plastic | D1: Individuals_Natural | E1: Individuals_plastic | F1: Simpson_1-D_Natural | G1: Simpson_1-Dplastic | H1: Shannon_H_Natural | I1: Shannon_Hplastic | J1: Evenness_e^H/S_Natural | K1: Evenness_e^H/Splastic_Natural
A2: 1 | B2: 20 | C2: 13 | D2: 59 | E2: 75 | F2: 0.7389 | G2: 0.5753 | H2: 2.104 | I2: 1.484 | J2: 0.4099 | K2: 0.3392
A3: 1 | B3: 19 | C3: 13 | D3: 65 | E3: 50 | F3: 0.872 | G3: 0.744 | H3: 2.428 | I3: 1.807 | J3: 0.5969 | K3: 0.4686 | L3: Plastic
A4: 1 | B4: 3 | C4: 9 | D4: 3 | E4: 34 | F4: 0.6667 | G4: 0.7059 | H4: 1.099 | I4: 1.638 | J4: 1 | K4: 0.5719
A5: 1 | B5: 12 | C5: 16 | D5: 384 | E5: 996 | F5: 0.3357 | G5: 0.2374 | H5: 0.7479 | I5: 0.5839 | J5: 0.1761 | K5: 0.1121 | L5: Natural
A6: 1 | B6: 17 | C6: 12 | D6: 309 | E6: 29 | F6: 0.3295 | G6: 0.8609 | H6: 0.8931 | I6: 2.22 | J6: 0.1437 | K6: 0.7673
A7: 1 | B7: 5 | C7: 11 | D7: 10 | E7: 70 | F7: 0.6 | G7: 0.7567 | H7: 1.228 | I7: 1.686 | J7: 0.6826 | K7: 0.4907
A8: 1 | B8: 14 | C8: 11 | D8: 200 | E8: 198 | F8: 0.3995 | G8: 0.5448 | H8: 1.046 | I8: 1.238 | J8: 0.2033 | K8: 0.3134
A9: 1 | B9: 17 | C9: 18 | D9: 926 | E9: 254 | F9: 0.2212 | G9: 0.5699 | H9: 0.5556 | I9: 1.432 | J9: 0.1025 | K9: 0.2325
A10: 1 | B10: 18 | C10: 20 | D10: 122 | E10: 120 | F10: 0.7932 | G10: 0.8463 | H10: 2.081 | I10: 2.261 | J10: 0.4451 | K10: 0.4795
A11: 1 | B11: 17 | C11: 23 | D11: 153 | E11: 90 | F11: 0.7419 | G11: 0.8701 | H11: 1.807 | I11: 2.519 | J11: 0.3584 | K11: 0.5397
A12: 2 | B12: 5 | C12: 15 | D12: 22 | E12: 89 | F12: 0.5372 | G12: 0.5194 | H12: 1.046 | I12: 1.383 | J12: 0.5692 | K12: 0.2657
A13: 2 | B13: 7 | C13: 5 | D13: 29 | E13: 7 | F13: 0.7134 | G13: 0.7755 | H13: 1.496 | I13: 1.55 | J13: 0.6375 | K13: 0.9421
A14: 2 | B14: 2 | C14: 4 | D14: 2 | E14: 6 | F14: 0.5 | G14: 0.6667 | H14: 0.6931 | I14: 1.242 | J14: 1 | K14: 0.866
A15: 2 | B15: 1 | C15: 4 | D15: 5 | E15: 12 | F15: 0 | G15: 0.6528 | H15: 0 | I15: 1.199 | J15: 1 | K15: 0.8291
A16: 2 | B16: 9 | C16: 4 | D16: 77 | E16: 21 | F16: 0.4574 | G16: 0.3946 | H16: 1.093 | I16: 0.7751 | J16: 0.3316 | K16: 0.5427
A17: 2 | B17: 5 | C17: 5 | D17: 32 | E17: 89 | F17: 0.582 | G17: 0.4623 | H17: 1.119 | I17: 0.8296 | J17: 0.6121 | K17: 0.4585
A18: 2 | B18: 3 | C18: 5 | D18: 14 | E18: 87 | F18: 0.5 | G18: 0.4341 | H18: 0.8305 | I18: 0.8955 | J18: 0.7648 | K18: 0.4897
A19: 2 | B19: 0 | C19: 9 | D19: 0 | E19: 60 | F19: 0 | G19: 0.7428 | H19: 0 | I19: 1.622 | J19: 0 | K19: 0.5627
A20: 2 | B20: 0 | C20: 13 | D20: 0 | E20: 48 | F20: 0 | G20: 0.7222 | H20: 0 | I20: 1.856 | J20: 0 | K20: 0.4922
A21: 2 | B21: 0 | C21: 3 | D21: 0 | E21: 4 | F21: 0 | G21: 0.625 | H21: 0 | I21: 1.04 | J21: 0 | K21: 0.9428
B24: Calculate (Means and SD) and/ or (Median with range) and fill the table I gave you on word
A26: mean | B26: =AVERAGE(B2:B21) -> 8.7 | C26: =AVERAGE(C2:C21) -> 10.65 | D26: =AVERAGE(D2:D21) -> 120.6 | E26: =AVERAGE(E2:E21) -> 116.95 | F26: =AVERAGE(F2:F21) -> 0 | G26: =AVERAGE(G2:G21) -> #DIV/0! | H26: =AVERAGE(H2:H21) -> 1.01336 | I26: =AVERAGE(I2:I21) -> #DIV/0! | ... K26: =AVERAGE(K2:K21) -> #DIV/0!
A27: SD | B27: =_xlfn.STDEV.P(B2:B21) -> 7.0929543 | C27: =_xlfn.STDEV.P(C2:C21) -> 5.7120487 | D27: =_xlfn.STDEV.P(D2:D21) -> 212.619 | E27: =_xlfn.STDEV.P(E2:E21) -> 210.91621 | F27: =_xlfn.STDEV.P(F2:F21) -> 0 | G27: =_xlfn.STDEV.P(G2:G21) -> #DIV/0! | H27: =_xlfn.STDEV.P(H2:H21) -> 0.70015978 | I27: =_xlfn.STDEV.P(I2:I21) -> #DIV/0! | ... K27: =_xlfn.STDEV.P(K2:K21) -> #DIV/0!
A28: Median | B28: =MEDIAN(B2:B21) -> 6 | C28: =MEDIAN(C2:C21) -> 11 | D28: =MEDIAN(D2:D21) -> 30.5 | E28: =MEDIAN(E2:E21) -> 65 | F28: =MEDIAN(F2:F21) -> 0 | G28: =MEDIAN(G2:G21) -> #NUM! | H28: =MEDIAN(H2:H21) -> 1.046 | I28: =MEDIAN(I2:I21) -> #NUM! | ... K28: =MEDIAN(K2:K21) -> #NUM!
A30: Min | B30: =MIN(B2:B21) -> 0 | C30: =MIN(C2:C21) -> 3 | D30: =MIN(D2:D21) -> 0 | E30: =MIN(E2:E21) -> 4 | F30: =MIN(F2:F21) -> 0 | G30: =MIN(G2:G21) -> 0 | H30: =MIN(H2:H21) -> 0 | I30: =MIN(I2:I21) -> 0 | ... K30: =MIN(K2:K21) -> 0
A31: Max | B31: =MAX(B2:B21) -> 20 | C31: =MAX(C2:C21) -> 23 | D31: =MAX(D2:D21) -> 926 | E31: =MAX(E2:E21) -> 996 | F31: =MAX(F2:F21) -> 0 | G31: =MAX(G2:G21) -> 0 | H31: =MAX(H2:H21) -> 2.428 | I31: =MAX(I2:I21) -> 0 | ... K31: =MAX(K2:K21) -> 0

Sheet Plastic vs natural results
A1: Species richness | B1: Spieces richness_plastic | F1: Simpson_1-D | G1: Simpson_1-Dplastic
A2: N: | B2: 20 | F2: N: | G2: 20
A3: Mean: | B3: 8.7 | C3: Mean: | D3: 10.65 | F3: Mean: | G3: 0.44943 | H3: Mean: | I3: 0.63534
A4: Median: | B4: 6 | C4: Median: | D4: 11 | F4: Median: | G4: 0.5 | H4: Median: | I4: 0.65975 | K4: Evenness_e^H/S | L4: Evenness_e^H/Splastic
K5: N: | L5: 20
A6: t test | F6: t test | K6: Mean: | L6: 0.45169 | M6: Mean: | N6: 0.53532
A7: Mean difference: | B7: 1.95 | C7: 95% conf.: | D7: (-0.629 4.529) | F7: Mean difference: | G7: 0.18591 | H7: 95% conf.: | I7: (0.042788 0.32902) | K7: Median: | L7: 0.4275 | M7: Median: | N7: 0.49145
A8: t : | B8: -1.5825 | C8: p (same mean): | D8: 0.13003 | F8: t : | G8: -2.7188 | H8: p (same mean): | I8: 0.013625
A9: Exact: | B9: p (same mean): | C9: 0.14046 | F9: Exact: | G9: p (same mean): | H9: 0.013786 | K9: t test
K10: Mean difference: | L10: 0.083635 | M10: 95% conf.: | N10: (-0.082055 0.24932)
A11: Sign test | F11: Sign test | K11: t : | L11: -1.0565 | M11: p (same mean): | N11: 0.30399
A12: r : | B12: 13 | C12: p (same median): | D12: 0.16707 | F12: r : | G12: 13 | H12: p (same median): | I12: 0.26318 | K12: Exact: | L12: p (same mean): | M12: 0.30899
A14: Wilcoxon test : | F14: Wilcoxon test : | K14: Sign test
A15: W : | B15: 129 | F15: W : | G15: 161 | K15: r : | L15: 10 | M15: p (same median): | N15: 0.8238
A16: Normal appr. z : | B16: 1.3717 | C16: p (same median): | D16: 0.17015 | F16: Normal appr. z : | G16: 2.0906 | H16: p (same median): | I16: 0.036561
A17: Monte Carlo (n=99999): | B17: p (same median): | C17: 0.17971 | F17: Monte Carlo (n=99999): | G17: p (same median): | H17: 0.03709 | K17: Wilcoxon test :
A18: Exact: | B18: p (same median): | C18: 0.17626 | F18: Exact: | G18: p (same median): | H18: 0.036234 | K18: W : | L18: 122
K19: Normal appr. z : | L19: 0.63466 | M19: p (same median): | N19: 0.52565
K20: Monte Carlo (n=99999): | L20: p (same median): | M20: 0.54624
K21: Exact: | L21: p (same median): | M21: 0.54588
A22: Individuals | B22: Individuals_plastic | F22: Shannon_H | G22: Shannon_Hplastic
A23: N: | B23: 20 | F23: N: | G23: 20
A24: Mean: | B24: 120.6 | C24: Mean: | D24: 116.95 | F24: Mean: | G24: 1.0134 | H24: Mean: | I24: 1.4631
A25: Median: | B25: 30.5 | C25: Median: | D25: 65 | F25: Median: | G25: 1.046 | H25: Median: | I25: 1.458
A27: t test | F27: t test
A28: Mean difference: | B28: 3.65 | C28: 95% conf.: | D28: (-100.22 107.52) | F28: Mean difference: | G28: 0.4497 | H28: 95% conf.: | I28: (0.11773 0.78166)
A29: t : | B29: 0.073546 | C29: p (same mean): | D29: 0.94214 | F29: t : | G29: -2.8353 | H29: p (same mean): | I29: 0.010577
A30: Exact: | B30: p (same mean): | C30: 0.9457 | F30: Exact: | G30: p (same mean): | H30: 0.010357
A32: Sign test | F32: Sign test
A33: r : | B33: 12 | C33: p (same median): | D33: 0.50344 | F33: r : | G33: 15 | H33: p (same median): | I33: 0.041389
A35: Wilcoxon test : | F35: Wilcoxon test :
A36: W : | B36: 129 | F36: W : | G36: 169
A37: Normal appr. z : | B37: 0.89622 | C37: p (same median): | D37: 0.37014 | F37: Normal appr. z : | G37: 2.3893 | H37: p (same median): | I37: 0.016881
A38: Monte Carlo (n=99999): | B38: p (same median): | C38: 0.38224 | F38: Monte Carlo (n=99999): | G38: p (same median): | H38: 0.01518
A39: Exact: | B39: p (same median): | C39: 0.38318 | F39: Exact: | G39: p (same median): | H39: 0.015312

Sheet S1 vs S2
A1: Substrate | B1: Taxa_Species richness | C1: Taxa_S_Season 2 | D1: Individuals/Abundance | E1: Individuals_Season 2 | F1: Simpson_1-D | G1: Simpson_1-D_Season 2 | H1: Shannon_H | I1: Shannon_H_Season 2 | J1: Evenness_e^H/S | K1: Evenness_e^H/S_Season 2 | L1: Margalef | M1: Margalef_Season 2
A2: N | B2: 20 | C2: 5 | D2: 59 | E2: 22 | F2: 0.7389 | G2: 0.5372 | H2: 2.104 | I2: 1.046 | J2: 0.4099 | K2: 0.5692 | L2: 4.66 | M2: 1.294
A3: N | B3: 19 | C3: 4 | D3: 65 | E3: 6 | F3: 0.872 | G3: 0.6667 | H3: 2.428 | I3: 1.242 | J3: 0.5969 | K3: 0.866 | L3: 4.312 | M3: 1.674
A4: N | B4: 3 | C4: 4 | D4: 3 | E4: 12 | F4: 0.6667 | G4: 0.6528 | H4: 1.099 | I4: 1.199 | J4: 1 | K4: 0.8291 | L4: 1.82 | M4: 1.207
A5: N | B5: 12 | C5: 4 | D5: 384 | E5: 21 | F5: 0.3357 | G5: 0.3946 | H5: 0.7479 | I5: 0.7751 | J5: 0.1761 | K5: 0.5427 | L5: 1.849 | M5: 0.9854
A6: N | B6: 17 | C6: 1 | D6: 309 | E6: 5 | F6: 0.3295 | G6: 0 | H6: 0.8931 | I6: 0 | J6: 0.1437 | K6: 1 | L6: 2.791 | M6: 0
A7: N | B7: 5 | C7: 9 | D7: 10 | E7: 60 | F7: 0.6 | G7: 0.7428 | H7: 1.228 | I7: 1.622 | J7: 0.6826 | K7: 0.5627 | L7: 1.737 | M7: 1.954
A8: N | B8: 14 | C8: 13 | D8: 200 | E8: 48 | F8: 0.3995 | G8: 0.7222 | H8: 1.046 | I8: 1.856 | J8: 0.2033 | K8: 0.4922 | L8: 2.454 | M8: 3.1
A9: N | B9: 17 | C9: 3 | D9: 926 | E9: 4 | F9: 0.2212 | G9: 0.625 | H9: 0.5556 | I9: 1.04 | J9: 0.1025 | K9: 0.9428 | L9: 2.342 | M9: 1.443
A10: N | B10: 18 | C10: 0 | D10: 122 | F10: 0.7932 | G10: 0 | H10: 2.081 | J10: 0.4451 | K10: 0 | L10: 3.539 | M10: 0
A11: N | B11: 17 | C11: 0 | D11: 153 | F11: 0.7419 | G11: 0 | H11: 1.807 | J11: 0.3584 | K11: 0 | L11: 3.181 | M11: 0
A12: P | B12: 13 | C12: 15 | D12: 75 | E12: 89 | F12: 0.5753 | G12: 0.5194 | H12: 1.484 | I12: 1.383 | J12: 0.3392 | K12: 0.2657 | L12: 2.779 | M12: 3.119
A13: P | B13: 13 | C13: 5 | D13: 50 | E13: 7 | F13: 0.744 | G13: 0.7755 | H13: 1.807 | I13: 1.55 | J13: 0.4686 | K13: 0.9421 | L13: 3.067 | M13: 2.056
A14: P | B14: 9 | C14: 7 | D14: 34 | E14: 29 | F14: 0.7059 | G14: 0.7134 | H14: 1.638 | I14: 1.496 | J14: 0.5719 | K14: 0.6375 | L14: 2.269 | M14: 1.782
A15: P | B15: 16 | C15: 2 | D15: 996 | E15: 2 | F15: 0.2374 | G15: 0.5 | H15: 0.5839 | I15: 0.6931 | J15: 0.1121 | K15: 1 | L15: 2.173 | M15: 1.443
A16: P | B16: 12 | C16: 5 | D16: 29 | E16: 89 | F16: 0.8609 | G16: 0.4623 | H16: 2.22 | I16: 0.8296 | J16: 0.7673 | K16: 0.4585 | L16: 3.267 | M16: 0.8911
A17: P | B17: 11 | C17: 5 | D17: 70 | E17: 87 | F17: 0.7567 | G17: 0.4341 | H17: 1.686 | I17: 0.8955 | J17: 0.4907 | K17: 0.4897 | L17: 2.354 | M17: 0.8957
A18: P | B18: 11 | C18: 9 | D18: 198 | E18: 77 | F18: 0.5448 | G18: 0.4574 | H18: 1.238 | I18: 1.093 | J18: 0.3134 | K18: 0.3316 | L18: 1.891 | M18: 1.842
A19: P | B19: 18 | C19: 5 | D19: 254 | E19: 32 | F19: 0.5699 | G19: 0.582 | H19: 1.432 | I19: 1.119 | J19: 0.2325 | K19: 0.6121 | L19: 3.07 | M19: 1.154
A20: P | B20: 20 | C20: 3 | D20: 120 | E20: 14 | F20: 0.8463 | G20: 0.5 | H20: 2.261 | I20: 0.8305 | J20: 0.4795 | K20: 0.7648 | L20: 3.969 | M20: 0.7578
A21: P | B21: 23 | C21: 0 | D21: 90 | F21: 0.8701 | G21: 0 | H21: 2.519 | J21: 0.5397 | K21: 0 | L21: 4.889 | M21: 0
A23: Mean | B23: =AVERAGE(B2:B21) -> 14.4 | C23: =AVERAGE(C2:C21) -> 4.95 | D23: =AVERAGE(D2:D21) -> 207.35 | E23: =AVERAGE(E2:E21) -> 35.529412 | F23: =AVERAGE(F2:F21) -> #DIV/0! | G23: =AVERAGE(G2:G21) -> 0 | H23: =AVERAGE(H2:H21) -> #DIV/0! | I23: =AVERAGE(I2:I21) -> 0 | ... M23: =AVERAGE(M2:M21) -> 0
A24: SD | B24: =_xlfn.STDEV.P(B2:B21) -> 4.9638695 | C24: =_xlfn.STDEV.P(C2:C21) -> 3.9430318 | D24: =_xlfn.STDEV.P(D2:D21) -> 270.17573 | E24: =_xlfn.STDEV.P(E2:E21) -> 31.663892 | F24: =_xlfn.STDEV.P(F2:F21) -> #DIV/0! | G24: =_xlfn.STDEV.P(G2:G21) -> 0 | H24: =_xlfn.STDEV.P(H2:H21) -> #DIV/0! | I24: =_xlfn.STDEV.P(I2:I21) -> 0 | ... M24: =_xlfn.STDEV.P(M2:M21) -> 0
A25: Median | B25: =MEDIAN('S1 vs S2'!B2:B21) -> 15 | C25: =MEDIAN('S1 vs S2'!C2:C21) -> 4.5 | D25: =MEDIAN('S1 vs S2'!D2:D21) -> 105 | E25: =MEDIAN('S1 vs S2'!E2:E21) -> 22 | F25: =MEDIAN('S1 vs S2'!F2:F21) -> #NUM! | G25: =MEDIAN('S1 vs S2'!G2:G21) -> 0 | H25: =MEDIAN('S1 vs S2'!H2:H21) -> #NUM! | I25: =MEDIAN('S1 vs S2'!I2:I21) -> 0 | ... M25: =MEDIAN('S1 vs S2'!M2:M21) -> 0
A27: Min | B27: =MIN(B2:B21) -> 3 | C27: =MIN(C2:C21) -> 0 | D27: =MIN(D2:D21) -> 3 | E27: =MIN(E2:E21) -> 2 | F27: =MIN(F2:F21) -> 0 | G27: =MIN(G2:G21) -> 0 | H27: =MIN(H2:H21) -> 0 | I27: =MIN(I2:I21) -> 0 | ... M27: =MIN(M2:M21) -> 0
A28: Max | B28: =MAX(B2:B21) -> 23 | C28: =MAX(C2:C21) -> 15 | D28: =MAX(D2:D21) -> 996 | E28: =MAX(E2:E21) -> 89 | F28: =MAX(F2:F21) -> 0 | G28: =MAX(G2:G21) -> 0 | H28: =MAX(H2:H21) -> 0 | I28: =MAX(I2:I21) -> 0 | ... M28: =MAX(M2:M21) -> 0

Sheet S1 VS S2 Results
B1: Species richness | H1: Abundance season 2 | M1: Eveness
A2: Taxa_S_Season1 | B2: Taxa_S_Season 2 | G2: Abundance_Season1 | H2: Abundance season 2 | L2: Evenness_e^H/S_Season1 | M2: Evenness_e^H/S_Season 2
A3: N: | B3: 20 | G3: N: | H3: 20 | L3: N: | M3: 20
A4: Mean: | B4: 14.4 | C4: Mean: | D4: 4.95 | G4: Mean: | H4: 207.35 | I4: Mean: | J4: 30.2 | L4: Mean: | M4: 0.42167 | N4: Mean: | O4: 0.56533
A5: Median: | B5: 15 | C5: Median: | D5: 4.5 | G5: Median: | H5: 105 | I5: Median: | J5: 17.5 | L5: Median: | M5: 0.4275 | N5: Median: | O5: 0.56595
A7: t test | G7: t test | L7: t test
A8: Mean difference: | B8: 9.45 | C8: 95% conf.: | D8: (5.8011 13.099) | G8: Mean difference: | H8: 177.15 | I8: 95% conf.: | J8: (41.646 312.65) | L8: Mean difference: | M8: 0.14367 | N8: 95% conf.: | O8: (-0.052769 0.3401)
A9: t : | B9: 5.4205 | C9: p (same mean): | D9: 3.1351E-05 | G9: t : | H9: 2.7363 | I9: p (same mean): | J9: 0.013118 | L9: t : | M9: -1.5308 | N9: p (same mean): | O9: 0.14231
A10: Exact: | B10: p (same mean): | C10: 9.1553E-05 | G10: Exact: | H10: p (same mean): | I10: 0.00065231 | L10: Exact: | M10: p (same mean): | N10: 0.14237
A12: Sign test | G12: Sign test | L12: Sign test
A13: r : | B13: 17 | C13: p (same median): | D13: 0.0025768 | G13: r : | H13: 15 | I13: p (same median): | J13: 0.041389 | L13: r : | M13: 12 | N13: p (same median): | O13: 0.50344
A15: Wilcoxon test : | G15: Wilcoxon test : | L15: Wilcoxon test :
A16: W : | B16: 198.5 | G16: W : | H16: 185 | L16: W : | M16: 138
A17: Normal appr. z : | B17: 3.4933 | C17: p (same median): | D17: 0.00047701 | G17: Normal appr. z : | H17: 2.9866 | I17: p (same median): | J17: 0.0028209 | L17: Normal appr. z : | M17: 1.232 | N17: p (same median): | O17: 0.21796
A18: Monte Carlo (n=99999): | B18: p (same median): | C18: 0.00012 | G18: Monte Carlo (n=99999): | H18: p (same median): | I18: 0.00185 | L18: Monte Carlo (n=99999): | M18: p (same median): | N18: 0.2289
A19: Exact: | B19: p (same median): | C19: 0.00011253 | G19: Exact: | H19: p (same median): | I19: 0.0016899 | L19: Exact: | M19: p (same median): | N19: 0.23051
B23: Simpson_ | H23: Shannon
A24: Simpson_1-D_Season1 | B24: Simpson_1-D_Season 2 | G24: Shannon_H_Season1 | H24: Shannon_H_Season 2
A25: N: | B25: 20 | G25: N: | H25: 20
A26: Mean: | B26: 0.6205 | C26: Mean: | D26: 0.46427 | G26: Mean: | H26: 1.5429 | I26: Mean: | J26: 0.93349
A27: Median: | B27: 0.6863 | C27: Median: | D27: 0.5097 | G27: Median: | H27: 1.561 | I27: Median: | J27: 1.043
A29: t test | G29: t test
A30: Mean difference: | B30: 0.15623 | C30: 95% conf.: | D30: (-0.0099373 0.32239) | G30: Mean difference: | H30: 0.60943 | I30: 95% conf.: | J30: (0.18366 1.0352)
A31: t : | B31: 1.9679 | C31: p (same mean): | D31: 0.063855 | G31: t : | H31: 2.9959 | I31: p (same mean): | J31: 0.0074293
A32: Exact: | B32: p (same mean): | C32: 0.064322 | G32: Exact: | H32: p (same mean): | I32: 0.0068626
A34: Sign test | G34: Sign test
A35: r : | B35: 12 | C35: p (same median): | D35: 0.50344 | G35: r : | H35: 14 | I35: p (same median): | J35: 0.11532
A37: Wilcoxon test : | G37: Wilcoxon test :
A38: W : | B38: 148 | G38: W : | H38: 172
A39: Normal appr. z : | B39: 1.6053 | C39: p (same median): | D39: 0.10843 | G39: Normal appr. z : | H39: 2.5013 | I39: p (same median): | J39: 0.012374
A40: Monte Carlo (n=99999): | B40: p (same median): | C40: 0.11346 | G40: Monte Carlo (n=99999): | H40: p (same median): | I40: 0.01102
A41: Exact: | B41: p (same median): | C41: 0.11399 | G41: Exact: | H41: p (same median): | I41: 0.010689

Sheet SIMPER results
A1: Taxon | B1: Av. dissim | C1: Contrib. % | D1: Cumulative % | E1: Mean Plastics | F1: Mean Natural
A2: Chironominae | B2: 19.96 | C2: 21.39 | D2: 21.39 | E2: 52.6 | F2: 32.3
A3: Tanypodinae | B3: 14.36 | C3: 15.39 | D3: 36.79 | E3: 16.9 | F3: 52
A4: Tanypodinae Tanypus | B4: 5.939 | C4: 6.365 | D4: 43.15 | E4: 10.5 | F4: 8.35
A5: Pseudosuccinea columella | B5: 3.195 | C5: 3.425 | D5: 46.58 | E5: 1.15 | F5: 0.75
A6: Bulinus natalensis | B6: 3.166 | C6: 3.394 | D6: 49.97 | E6: 2.75 | F6: 0.1
A7: Hydropsyche | B7: 3.119 | C7: 3.343 | D7: 53.31 | E7: 0.35 | F7: 4.35
A8: Tubifex | B8: 3.021 | C8: 3.238 | D8: 56.55 | E8: 4.8 | F8: 1.4
A9: Salifidae | B9: 2.779 | C9: 2.979 | D9: 59.53 | E9: 2.15 | F9: 1.2
A10: Radix natalensis | B10: 2.755 | C10: 2.953 | D10: 62.48 | E10: 1.45 | F10: 1.1
A11: Sub Imago | B11: 2.466 | C11: 2.643 | D11: 65.13 | E11: 3.3 | F11: 0
A12: Paracnephia | B12: 2.161 | C12: 2.317 | D12: 67.44 | E12: 1.9 | F12: 0.75
A13: Atherix | B13: 2.048 | C13: 2.195 | D13: 69.64 | E13: 2.4 | F13: 0
A14: Cheleocloeon | B14: 1.974 | C14: 2.116 | D14: 71.75 | E14: 0.75 | F14: 1.65
A15: Cloeon | B15: 1.872 | C15: 2.006 | D15: 73.76 | E15: 0.3 | F15: 1.75
A16: Macrobacium | B16: 1.524 | C16: 1.633 | D16: 75.39 | E16: 0.3 | F16: 1.45
A17: Imago | B17: 1.381 | C17: 1.48 | D17: 76.87 | E17: 0.45 | F17: 1.65
A18: Simulium | B18: 1.316 | C18: 1.411 | D18: 78.28 | E18: 1.1 | F18: 0.1
A19: Helisoma duryi | B19: 1.26 | C19: 1.35 | D19: 79.63 | E19: 0.5 | F19: 0.45
A20: Thylakion | B20: 1.23 | C20: 1.318 | D20: 80.95 | E20: 0.65 | F20: 0.9
A21: Caridina | B21: 1.094 | C21: 1.173 | D21: 82.12 | E21: 0 | F21: 0.7
A22: Bulinus africanus | B22: 0.9727 | C22: 1.042 | D22: 83.17 | E22: 1.65 | F22: 0.15
A23: Eristalis | B23: 0.896 | C23: 0.9603 | D23: 84.13 | E23: 1.15 | F23: 0.85
A24: Dasyhelea | B24: 0.8858 | C24: 0.9494 | D24: 85.08 | E24: 0.65 | F24: 0.7
A25: Pseudagrion | B25: 0.8646 | C25: 0.9266 | D25: 86 | E25: 0.55 | F25: 0.15
A26: Noteridae | B26: 0.7315 | C26: 0.784 | D26: 86.79 | E26: 0.1 | F26: 0
A27: Roundworms | B27: 0.6143 | C27: 0.6584 | D27: 87.45 | E27: 0.7 | F27: 0
A28: Trithemis | B28: 0.6107 | C28: 0.6545 | D28: 88.1 | E28: 0.4 | F28: 0.15
A29: L.Plagiatus | B29: 0.5936 | C29: 0.6362 | D29: 88.74 | E29: 0 | F29: 0.4
A30: Clogmia | B30: 0.593 | C30: 0.6355 | D30: 89.37 | E30: 0.85 | F30: 0.4
A31: Baetis harrisoni | B31: 0.5746 | C31: 0.6159 | D31: 89.99 | E31: 0.2 | F31: 0
A32: Marsupiobdella Africana | B32: 0.5401 | C32: 0.5789 | D32: 90.57 | E32: 0.15 | F32: 0.15
A33: Psychoda | B33: 0.4012 | C33: 0.43 | D33: 91 | E33: 0.7 | F33: 0.5
A34: Ceratopogoninae | B34: 0.3529 | C34: 0.3782 | D34: 91.37 | E34: 0.2 | F34: 0
A35: Culicoides | B35: 0.3453 | C35: 0.3701 | D35: 91.74 | E35: 0.15 | F35: 0.15
A36: Paracnomina | B36: 0.3433 | C36: 0.3679 | D36: 92.11 | E36: 0.1 | F36: 0.25
A37: Platychauliodes | B37: 0.3217 | C37: 0.3448 | D37: 92.46 | E37: 0.1 | F37: 0.05
A38: Lymnaea truncatula | B38: 0.2935 | C38: 0.3146 | D38: 92.77 | E38: 0 | F38: 0.25
A39: Melanoides tuberculata | B39: 0.2744 | C39: 0.294 | D39: 93.07 | E39: 0.05 | F39: 0
A40: Culicid pupae | B40: 0.2656 | C40: 0.2847 | D40: 93.35 | E40: 0.35 | F40: 0.45
...

Sheet PERMANOVA results macoinverts
A1: PERMANOVA
A3: Permutation N: | B3: 9999
A4: Total sum of squares: | B4: 1.569E06
A5: Within-group sum of squares: | B5: 1.477E06
A6: F: | B6: 2.343
A7: p (same): | B7: 0.0118
A13: Factor / Model | B13: df | C13: Sum of Squares | D13: R² | E13: F.Model | F13: p-value
A14: Substrate | B14: 1 | C14: 0.295 | D14: 0.023 | E14: 0.820 | F14: 0.711
A15: Season | B15: 1 | C15: 0.816 | D15: 0.063 | E15: 2.369 | F15: 0.001***
A16: Substrate × Season | B16: 3 | C16: 1.493 | D16: 0.116 | E16: 1.443 | F16: 0.017*
A17: Full model (Substrate × Season + environmental variables) | B17: 13 | C17: 6.632 | D17: 0.515 | E17: 1.879 | F17: 0.001***

Sheet Sheet8
